Workbook

Sheet DATA
A1: MCDM— Données (9 critères)
A2: Alternative | B2: EF Single score | C2: Density (g/cm³) | D2: Tensile Modulus (GPa) | E2: Tensile Strength (MPa) | F2: Elongation at break (%) | G2: Flexural modulus (GPa) | H2: Flexural strength (MPa) | I2: CTE (µm/m·°C) | J2: Raw material cost (€/kg) | K2: Toggle mode
A3: Sens (benefice/cout) | B3: cout | C3: cout | D3: benefice | E3: benefice | F3: benefice | G3: benefice | H3: benefice | I3: cout | J3: cout | K3: CRITIC
A4: Weight (somme = 1) | B4: 0.11111 | C4: 0.11111 | D4: 0.11111 | E4: 0.11111 | F4: 0.11111 | G4: 0.11111 | H4: 0.11111 | I4: 0.11111 | J4: 0.11111 | L4: Somme des poids: | M4: =SUM(B4:J4) -> 0.99999
A6: Random weight | B6: =RAND()+0*MATCH($K$3,{"MANUEL","ALEA"},0) -> #N/A | C6: =RAND()+0*MATCH($K$3,{"MANUEL","ALEA"},0) -> #N/A | D6: =RAND()+0*MATCH($K$3,{"MANUEL","ALEA"},0) -> #N/A | E6: =RAND()+0*MATCH($K$3,{"MANUEL","ALEA"},0) -> #N/A | F6: =RAND()+0*MATCH($K$3,{"MANUEL","ALEA"},0) -> #N/A | G6: =RAND()+0*MATCH($K$3,{"MANUEL","ALEA"},0) -> #N/A | H6: =RAND()+0*MATCH($K$3,{"MANUEL","ALEA"},0) -> #N/A | I6: =RAND()+0*MATCH($K$3,{"MANUEL","ALEA"},0) -> #N/A | J6: =RAND()+0*MATCH($K$3,{"MANUEL","ALEA"},0) -> #N/A
A7: Effective weight | B7: {=IF($K$3="ALEA",B6/SUM($B$6:$J$6), IF($K$3="CRITIC",INDEX(TOPSIS!$L$134:$T$134,1,COLUMN()-1), IF($K$3="ENTROPY",INDEX(TOPSIS!$L$366:$T$366,1,COLUMN()-1), B4)))} -> 0.10360018 | C7: {=IF($K$3="ALEA",C6/SUM($B$6:$J$6), IF($K$3="CRITIC",INDEX(TOPSIS!$L$134:$T$134,1,COLUMN()-1), IF($K$3="ENTROPY",INDEX(TOPSIS!$L$366:$T$366,1,COLUMN()-1), C4)))} -> 0.10681275 | D7: {=IF($K$3="ALEA",D6/SUM($B$6:$J$6), IF($K$3="CRITIC",INDEX(TOPSIS!$L$134:$T$134,1,COLUMN()-1), IF($K$3="ENTROPY",INDEX(TOPSIS!$L$366:$T$366,1,COLUMN()-1), D4)))} -> 0.079132717 | E7: {=IF($K$3="ALEA",E6/SUM($B$6:$J$6), IF($K$3="CRITIC",INDEX(TOPSIS!$L$134:$T$134,1,COLUMN()-1), IF($K$3="ENTROPY",INDEX(TOPSIS!$L$366:$T$366,1,COLUMN()-1), E4)))} -> 0.097058973 | F7: {=IF($K$3="ALEA",F6/SUM($B$6:$J$6), IF($K$3="CRITIC",INDEX(TOPSIS!$L$134:$T$134,1,COLUMN()-1), IF($K$3="ENTROPY",INDEX(TOPSIS!$L$366:$T$366,1,COLUMN()-1), F4)))} -> 0.10913698 | G7: {=IF($K$3="ALEA",G6/SUM($B$6:$J$6), IF($K$3="CRITIC",INDEX(TOPSIS!$L$134:$T$134,1,COLUMN()-1), IF($K$3="ENTROPY",INDEX(TOPSIS!$L$366:$T$366,1,COLUMN()-1), G4)))} -> 0.077157486 | H7: {=IF($K$3="ALEA",H6/SUM($B$6:$J$6), IF($K$3="CRITIC",INDEX(TOPSIS!$L$134:$T$134,1,COLUMN()-1), IF($K$3="ENTROPY",INDEX(TOPSIS!$L$366:$T$366,1,COLUMN()-1), H4)))} -> 0.087306732 | I7: {=IF($K$3="ALEA",I6/SUM($B$6:$J$6), IF($K$3="CRITIC",INDEX(TOPSIS!$L$134:$T$134,1,COLUMN()-1), IF($K$3="ENTROPY",INDEX(TOPSIS!$L$366:$T$366,1,COLUMN()-1), I4)))} -> 0.22601941 | J7: {=IF($K$3="ALEA",J6/SUM($B$6:$J$6), IF($K$3="CRITIC",INDEX(TOPSIS!$L$134:$T$134,1,COLUMN()-1), IF($K$3="ENTROPY",INDEX(TOPSIS!$L$366:$T$366,1,COLUMN()-1), J4)))} -> 0.11377476 | L7: Somme des poids ALEA: | M7: =SUM(B7:J7) -> 1
A8: Flax/Epoxy | B8: =ROUND('LCA Criteria'!I33,2) -> 0.59 | C8: 1.35 | D8: 35 | E8: 610 | F8: 1.8 | G8: 39 | H8: 520 | I8: =20*10^-6 -> 2e-05 | J8: 3.8
A9: Carbon/Epoxy | B9: =ROUND('LCA Criteria'!J33,2) -> 4.98 | C9: 1.42 | D9: 120 | E9: 2135 | F9: 1.15 | G9: 134 | H9: 1815 | I9: =2.98*10^-6 -> 2.98e-06 | J9: 20
A10: Glass/Epoxy | B10: =ROUND('LCA Criteria'!K33,2) -> 0.69 | C10: 1.8 | D10: 40 | E10: 1135 | F10: 1.3 | G10: 43 | H10: 965 | I10: =35*10^-6 -> 3.5e-05 | J10: 4
A11: Aluminium template | B11: =ROUND('LCA Criteria'!L33,2) -> 1.58 | C11: 2.7 | D11: 70 | E11: 330 | F11: 3.4 | G11: 70 | H11: 325 | I11: =23*10^-6 -> 2.3e-05 | J11: 10
A12: Chromium steel template | B12: =ROUND('LCA Criteria'!M33,2) -> 0.77 | C12: 7.9 | D12: 200 | E12: 750 | F12: 40 | G12: 200 | H12: 900 | I12: =17*10^-6 -> 1.7e-05 | J12: 2.5
A13: Hemp/Epoxy | B13: =ROUND('LCA Criteria'!N33,2) -> 0.55 | C13: 1.31 | D13: 28 | E13: 398 | F13: 2 | G13: 32 | H13: 340 | I13: =25*10^-6 -> 2.5e-05 | J13: 4
A14: Jute/epoxy | B14: =ROUND('LCA Criteria'!O33,2) -> 0.57 | C14: 1.3 | D14: 12 | E14: 335 | F14: 2.5 | G14: 13 | H14: 285 | I14: =30*10^-6 -> 3e-05 | J14: 3

Sheet LCA Criteria
A1: Alternative | B1: Single Score(mpoints) | C1: Acidification (mol H+-Eq) | D1: Climate change (kg CO2-Eq) | E1: Climate change: biogenic (kg CO2-Eq) | F1: Climate change: fossil (kg CO2-Eq) | G1: Climate change: land use and land use change (kg CO2-Eq) | H1: Ecotoxicity: freshwater (CTUe) | I1: Energy resources: non-renewable (MJ, net calorific value) | J1: Eutrophication: freshwater (kg P-Eq) | K1: Eutrophication: marine (kg N-Eq) | L1: Eutrophication: terrestrial (mol N-Eq) | M1: Human toxicity: carcinogenic (CTUh) | N1: Human toxicity: non-carcinogenic (CTUh) | O1: Ionising radiation: human health (kBq U235-Eq) | P1: Land use (dimensionless) | Q1: Material resources: metals/minerals (kg Sb-Eq) | R1: Ozone depletion (kg CFC-11-Eq) | S1: Particulate matter formation (disease incidence) | T1: Photochemical oxidant formation: human health (kg NMVOC-Eq) | U1: Water use (m3 world Eq deprived)
A2: Aluminium 1kg | C2: 0.12997026 | D2: 19.636295 | E2: 0.020510319 | F2: 19.559965 | G2: 0.055819949 | H2: 53.715198 | I2: 185.75991 | J2: 0.0058272202 | K2: 0.021128933 | L2: 0.2200101 | M2: 3.9856256e-08 | N2: 1.3863527e-07 | O2: 0.32865527 | P2: 30.517278 | Q2: 1.5797157e-05 | R2: 1.0372692e-07 | S2: 1.6334724e-06 | T2: 0.068474327 | U2: 4.7864387
A3: Flax/Epoxy | B3: 0.59156457 | C3: 0.018954804 | D3: 4.651546 | E3: 0.0055066752 | F3: 4.64144 | G3: 0.0045994028 | H3: 131.04868 | I3: 91.05046 | J3: 0.00117 | K3: 0.0381 | L3: 0.03855 | M3: 5.46004e-08 | N3: 4.7946e-08 | O3: 0.22894 | P3: 21.36012 | Q3: 4.38639e-05 | R3: 1.62732e-07 | S3: 2.0782e-07 | T3: 0.01852 | U3: 1.27503
A4: Hemp/Epoxy | B4: =O33 -> 0.56533715 | C4: 0.019239795 | D4: 4.6934657 | E4: 0.017119393 | F4: 4.6637926 | G4: 0.012553699 | H4: 161.77595 | I4: 91.311484 | J4: 0.0012933049 | K4: 0.0043638098 | L4: 0.040000981 | M4: 5.4666174e-08 | N4: 3.7645498e-08 | O4: 0.22896823 | P4: 30.611873 | Q4: 4.4024576e-05 | R4: 1.6273539e-07 | S4: 2.3337268e-07 | T4: 0.018744573 | U4: 2.1530622
A5: Carbon/Epoxy | B5: 4.9819 | C5: 0.25 | D5: 72.32 | H5: 841.9 | I5: 1051.02 | J5: 0.01 | K5: 0.06 | L5: 0.49 | M5: 1.62e-08 | N5: 3.36e-07 | O5: 3.61 | P5: 72.96 | Q5: 8.87e-05 | R5: 4.44e-06 | S5: 1.44e-06 | T5: 0.13 | U5: 12.23
A6: Glass/Epoxy | B6: 0.68826706 | C6: 0.02325 | D6: 4.37619 | E6: 0.00366 | F6: 4.3693 | G6: 0.00322 | H6: 103.39649 | I6: 71.67328 | J6: 0.00116 | K6: 0.00468 | L6: 0.04939 | M6: 3.58065e-08 | N6: 1.11471e-07 | O6: 0.28766 | P6: 12.62703 | Q6: 0.00021 | R6: 1.14085e-07 | S6: 2.1209e-07 | T6: 0.01894 | U6: 1.04844
A7: Aluminium template | B7: 1.5841711 | C7: 0.12997026 | D7: 19.636295 | E7: 0.020510319 | F7: 19.559965 | G7: 0.055819949 | H7: 53.715198 | I7: 185.75991 | J7: 0.0058272202 | K7: 0.021128933 | L7: 0.2200101 | M7: 3.9856256e-08 | N7: 1.3863527e-07 | O7: 0.32865527 | P7: 30.517278 | Q7: 1.5797157e-05 | R7: 1.0372692e-07 | S7: 1.6334724e-06 | T7: 0.068474327 | U7: 4.7864387
A8: Jute/Epoxy | B8: =N33 -> 0.55484767 | C8: 0.019359261 | D8: 4.678526 | E8: 0.010505244 | F8: 4.6446814 | G8: 0.02333938 | H8: 138.24778 | I8: 91.020188 | J8: 0.0012198603 | K8: 0.0041632103 | L8: 0.040836561 | M8: 5.4526932e-08 | N8: 3.7138912e-08 | O8: 0.22872396 | P8: 17.716616 | Q8: 4.3946282e-05 | R8: 1.6182487e-07 | S8: 2.2620847e-07 | T8: 0.018531802 | U8: 2.4853683
A9: Steel template | B9: =M33 -> 0.7662311 | C9: 0.029017352 | D9: 5.3190926 | E9: 0.0049170595 | F9: 5.3100746 | G9: 0.0041009296 | H9: 54.390427 | I9: 59.15589 | J9: 0.0017198526 | K9: 0.0052918678 | L9: 0.05630778 | M9: 1.389031e-07 | N9: 1.0855902e-07 | O9: 0.33889254 | P9: 26.499945 | Q9: 0.0001264079 | R9: 3.7965077e-08 | S9: 4.3470353e-07 | T9: 0.018003457 | U9: 1.6102484
A13: Impact categories | B13: Flax/Epoxy | C13: Carbon/Epoxy | D13: Glass/Epoxy | E13: Aluminium | F13: Steel template | G13: Jute/Epoxy | H13: Hemp/Epoxy | I13: ="Single Score " & B13 -> Single Score Flax/Epoxy | J13: ="Single Score " & C13 -> Single Score Carbon/Epoxy | K13: ="Single Score " & D13 -> Single Score Glass/Epoxy | L13: ="Single Score " & E13 -> Single Score Aluminium | M13: ="Single Score " & F13 -> Single Score Steel template | N13: ="Single Score " & G13 -> Single Score Jute/Epoxy | O13: ="Single Score " & H13 -> Single Score Hemp/Epoxy | P13: Normalisation factor per persona | Q13: Ponderation factor
A14: Acidification (mol H+-Eq) | B14: 0.018954804 | C14: 0.25 | D14: 0.02325 | E14: 0.12997026 | F14: 0.029017352 | G14: 0.019359261 | H14: 0.019239795 | I14: =((B14/$P14)*$Q14)*10^3 -> 0.021136652 | J14: =((C14/$P14)*$Q14)*10^3 -> 0.27877698 | K14: =((D14/$P14)*$Q14)*10^3 -> 0.025926259 | L14: =((E14/$P14)*$Q14)*10^3 -> 0.14493087 | M14: =((F14/$P14)*$Q14)*10^3 -> 0.032357479 | N14: =((G14/$P14)*$Q14)*10^3 -> 0.021587665 | O14: =((H14/$P14)*$Q14)*10^3 -> 0.021454447 | P14: 55.6 | Q14: 0.062
A15: Climate change (kg CO2-Eq) | B15: 4.651546 | C15: 72.32 | D15: 4.37619 | E15: 19.636295 | F15: 5.3190926 | G15: 4.678526 | H15: 4.6934657 | I15: =((B15/$P15)*$Q15)*10^3 -> 0.12975041 | J15: =((C15/$P15)*$Q15)*10^3 -> 2.017297 | K15: =((D15/$P15)*$Q15)*10^3 -> 0.12206962 | L15: =((E15/$P15)*$Q15)*10^3 -> 0.5477356 | M15: =((F15/$P15)*$Q15)*10^3 -> 0.14837098 | N15: =((G15/$P15)*$Q15)*10^3 -> 0.13050299 | O15: =((H15/$P15)*$Q15)*10^3 -> 0.13091972 | P15: 7550 | Q15: 0.2106
A16: Climate change: biogenic (kg CO2-Eq) | B16: 0.0055066752 | C16: 0 | D16: 0.00366 | E16: 0.020510319 | F16: 0.0049170595 | G16: 0.010505244 | H16: 0.017119393
A17: Climate change: fossil (kg CO2-Eq) | B17: 4.64144 | C17: 0 | D17: 4.3693 | E17: 19.559965 | F17: 5.3100746 | G17: 4.6446814 | H17: 4.6637926
A18: Climate change: land use and land use change (kg CO2-Eq) | B18: 0.0045994028 | C18: 0 | D18: 0.00322 | E18: 0.055819949 | F18: 0.0041009296 | G18: 0.02333938 | H18: 0.012553699
A19: Ecotoxicity: freshwater (CTUe) | B19: 131.04868 | C19: 841.9 | D19: 103.39649 | E19: 53.715198 | F19: 54.390427 | G19: 138.24778 | H19: 161.77595 | I19: =((B19/$P19)*$Q19)*10^3 -> 0.044376273 | J19: =((C19/$P19)*$Q19)*10^3 -> 0.28508783 | K19: =((D19/$P19)*$Q19)*10^3 -> 0.035012568 | L19: =((E19/$P19)*$Q19)*10^3 -> 0.018189273 | M19: =((F19/$P19)*$Q19)*10^3 -> 0.018417922 | N19: =((G19/$P19)*$Q19)*10^3 -> 0.046814063 | O19: =((H19/$P19)*$Q19)*10^3 -> 0.054781275 | P19: 56700 | Q19: 0.0192
A20: Energy resources: non-renewable (MJ, net calorific value) | B20: 91.05046 | C20: 1051.02 | D20: 71.67328 | E20: 185.75991 | F20: 59.15589 | G20: 91.020188 | H20: 91.311484 | I20: =((B20/$P20)*$Q20)*10^3 -> 0.11654459 | J20: =((C20/$P20)*$Q20)*10^3 -> 1.3453056 | K20: =((D20/$P20)*$Q20)*10^3 -> 0.091741798 | L20: =((E20/$P20)*$Q20)*10^3 -> 0.23777269 | M20: =((F20/$P20)*$Q20)*10^3 -> 0.075719539 | N20: =((G20/$P20)*$Q20)*10^3 -> 0.11650584 | O20: =((H20/$P20)*$Q20)*10^3 -> 0.1168787 | P20: 65000 | Q20: 0.0832
A21: Eutrophication: freshwater (kg P-Eq) | B21: 0.00117 | C21: 0.01 | D21: 0.00116 | E21: 0.0058272202 | F21: 0.0017198526 | G21: 0.0012198603 | H21: 0.0012933049 | I21: =((B21/$P21)*$Q21)*10^3 -> 0.020347826 | J21: =((C21/$P21)*$Q21)*10^3 -> 0.17391304 | K21: =((D21/$P21)*$Q21)*10^3 -> 0.020173913 | L21: =((E21/$P21)*$Q21)*10^3 -> 0.10134296 | M21: =((F21/$P21)*$Q21)*10^3 -> 0.02991048 | N21: =((G21/$P21)*$Q21)*10^3 -> 0.021214962 | O21: =((H21/$P21)*$Q21)*10^3 -> 0.02249226 | P21: 1.61 | Q21: 0.028
A22: Eutrophication: marine (kg N-Eq) | B22: 0.0381 | C22: 0.06 | D22: 0.00468 | E22: 0.021128933 | F22: 0.0052918678 | G22: 0.0041632103 | H22: 0.0043638098 | I22: =((B22/$P22)*$Q22)*10^3 -> 0.057833846 | J22: =((C22/$P22)*$Q22)*10^3 -> 0.091076923 | K22: =((D22/$P22)*$Q22)*10^3 -> 0.007104 | L22: =((E22/$P22)*$Q22)*10^3 -> 0.032072636 | M22: =((F22/$P22)*$Q22)*10^3 -> 0.008032784 | N22: =((G22/$P22)*$Q22)*10^3 -> 0.0063195397 | O22: =((H22/$P22)*$Q22)*10^3 -> 0.0066240395 | P22: 19.5 | Q22: 0.0296
A23: Eutrophication: terrestrial (mol N-Eq) | B23: 0.03855 | C23: 0.49 | D23: 0.04939 | E23: 0.2200101 | F23: 0.05630778 | G23: 0.040836561 | H23: 0.040000981 | I23: =((B23/$P23)*$Q23)*10^3 -> 0.0080802542 | J23: =((C23/$P23)*$Q23)*10^3 -> 0.10270621 | K23: =((D23/$P23)*$Q23)*10^3 -> 0.010352367 | L23: =((E23/$P23)*$Q23)*10^3 -> 0.046115112 | M23: =((F23/$P23)*$Q23)*10^3 -> 0.011802365 | N23: =((G23/$P23)*$Q23)*10^3 -> 0.0085595277 | O23: =((H23/$P23)*$Q23)*10^3 -> 0.0083843864 | P23: 177 | Q23: 0.0371
A24: Human toxicity: carcinogenic (CTUh) | B24: 5.46004e-08 | C24: 1.62e-08 | D24: 3.58065e-08 | E24: 3.9856256e-08 | F24: 1.389031e-07 | G24: 5.4526932e-08 | H24: 5.4666174e-08 | I24: =((B24/$P24)*$Q24)*10^3 -> 0.06722477 | J24: =((C24/$P24)*$Q24)*10^3 -> 0.019945665 | K24: =((D24/$P24)*$Q24)*10^3 -> 0.04408546 | L24: =((E24/$P24)*$Q24)*10^3 -> 0.049071575 | M24: =((F24/$P24)*$Q24)*10^3 -> 0.17101942 | N24: =((G24/$P24)*$Q24)*10^3 -> 0.067134316 | O24: =((H24/$P24)*$Q24)*10^3 -> 0.067305752 | P24: 1.73e-05 | Q24: 0.0213
A25: Human toxicity: non-carcinogenic (CTUh) | B25: 4.7946e-08 | C25: 3.36e-07 | D25: 1.11471e-07 | E25: 1.3863527e-07 | F25: 1.0855902e-07 | G25: 3.7138912e-08 | H25: 3.7645498e-08 | I25: =((B25/$P25)*$Q25)*10^3 -> 0.0068388093 | J25: =((C25/$P25)*$Q25)*10^3 -> 0.047925581 | K25: =((D25/$P25)*$Q25)*10^3 -> 0.01589974 | L25: =((E25/$P25)*$Q25)*10^3 -> 0.019774333 | M25: =((F25/$P25)*$Q25)*10^3 -> 0.015484387 | N25: =((G25/$P25)*$Q25)*10^3 -> 0.0052973331 | O25: =((H25/$P25)*$Q25)*10^3 -> 0.0053695905 | P25: 0.000129 | Q25: 0.0184
A26: Ionising radiation: human health (kBq U235-Eq) | B26: 0.22894 | C26: 3.61 | D26: 0.28766 | E26: 0.32865527 | F26: 0.33889254 | G26: 0.22872396 | H26: 0.22896823 | I26: =((B26/$P26)*$Q26)*10^3 -> 0.0027179844 | J26: =((C26/$P26)*$Q26)*10^3 -> 0.042858057 | K26: =((D26/$P26)*$Q26)*10^3 -> 0.0034151104 | L26: =((E26/$P26)*$Q26)*10^3 -> 0.0039018078 | M26: =((F26/$P26)*$Q26)*10^3 -> 0.0040233451 | N26: =((G26/$P26)*$Q26)*10^3 -> 0.0027154195 | O26: =((H26/$P26)*$Q26)*10^3 -> 0.0027183195 | P26: 4220 | Q26: 0.0501
A27: Land use (dimensionless) | B27: 21.36012 | C27: 72.96 | D27: 12.62703 | E27: 30.517278 | F27: 26.499945 | G27: 17.716616 | H27: 30.611873 | I27: =((B27/$P27)*$Q27)*10^3 -> 0.0020708102 | J27: =((C27/$P27)*$Q27)*10^3 -> 0.0070732894 | K27: =((D27/$P27)*$Q27)*10^3 -> 0.001224159 | L27: =((E27/$P27)*$Q27)*10^3 -> 0.0029585737 | M27: =((F27/$P27)*$Q27)*10^3 -> 0.0025691033 | N27: =((G27/$P27)*$Q27)*10^3 -> 0.0017175816 | O27: =((H27/$P27)*$Q27)*10^3 -> 0.0029677445 | P27: 819000 | Q27: 0.0794
A28: Material resources: metals/minerals (kg Sb-Eq) | B28: 4.38639e-05 | C28: 8.87e-05 | D28: 0.00021 | E28: 1.5797157e-05 | F28: 0.0001264079 | G28: 4.3946282e-05 | H28: 4.4024576e-05 | I28: =((B28/$P28)*$Q28)*10^3 -> 0.052071139 | J28: =((C28/$P28)*$Q28)*10^3 -> 0.10529638 | K28: =((D28/$P28)*$Q28)*10^3 -> 0.24929245 | L28: =((E28/$P28)*$Q28)*10^3 -> 0.018752915 | M28: =((F28/$P28)*$Q28)*10^3 -> 0.1500597 | N28: =((G28/$P28)*$Q28)*10^3 -> 0.052168935 | O28: =((H28/$P28)*$Q28)*10^3 -> 0.052261878 | P28: 0.0636 | Q28: 0.0755
A29: Ozone depletion (kg CFC-11-Eq) | B29: 1.62732e-07 | C29: 4.44e-06 | D29: 1.14085e-07 | E29: 1.0372692e-07 | F29: 3.7965077e-08 | G29: 1.6182487e-07 | H29: 1.6273539e-07 | I29: =((B29/$P29)*$Q29)*10^3 -> 0.00019633631 | J29: =((C29/$P29)*$Q29)*10^3 -> 0.0053568642 | K29: =((D29/$P29)*$Q29)*10^3 -> 0.00013764366 | L29: =((E29/$P29)*$Q29)*10^3 -> 0.00012514663 | M29: =((F29/$P29)*$Q29)*10^3 -> 4.5804902e-05 | N29: =((G29/$P29)*$Q29)*10^3 -> 0.00019524186 | O29: =((H29/$P29)*$Q29)*10^3 -> 0.0001963404 | P29: 0.0523 | Q29: 0.0631
A30: Particulate matter formation (disease incidence) | B30: 2.0782e-07 | C30: 1.44e-06 | D30: 2.1209e-07 | E30: 1.6334724e-06 | F30: 4.3470353e-07 | G30: 2.2620847e-07 | H30: 2.3337268e-07 | I30: =((B30/$P30)*$Q30)*10^3 -> 0.031295247 | J30: =((C30/$P30)*$Q30)*10^3 -> 0.21684706 | K30: =((D30/$P30)*$Q30)*10^3 -> 0.031938259 | L30: =((E30/$P30)*$Q30)*10^3 -> 0.24598172 | M30: =((F30/$P30)*$Q30)*10^3 -> 0.065461237 | N30: =((G30/$P30)*$Q30)*10^3 -> 0.034064334 | O30: =((H30/$P30)*$Q30)*10^3 -> 0.03514318 | P30: 0.000595 | Q30: 0.0896
... A32: Water use (m3 world Eq deprived) | B32: 1.27503 | C32: 12.23 | D32: 1.04844 | E32: 4.7864387 | F32: 1.6102484 | G32: 2.4853683 | H32: 2.1530622 | I32: =((B32/$P32)*$Q32)*10^3 -> 0.009435222 | J32: =((C32/$P32)*$Q32)*10^3 -> 0.090502 | K32: =((D32/$P32)*$Q32)*10^3 -> 0.007758456 | L32: =((E32/$P32)*$Q32)*10^3 -> 0.035419646 | M32: =((F32/$P32)*$Q32)*10^3 -> 0.011915838 | N32: =((G32/$P32)*$Q32)*10^3 -> 0.018391725 | O32: =((H32/$P32)*$Q32)*10^3 -> 0.01593266 | P32: 11500 | Q32: 0.0851
A33: Single score | I33: =SUM(I14:I32) -> 0.59156457 | J33: =SUM(J14:J32) -> 4.9819 | K33: =SUM(K14:K32) -> 0.68826706 | L33: =SUM(L14:L32) -> 1.5841711 | M33: =SUM(M14:M32) -> 0.7662311 | N33: =SUM(N14:N32) -> 0.55484767 | O33: =SUM(O14:O32) -> 0.56533715

Sheet TOPSIS
A1: Calcul TOPSIS
A2: Sens | B2: =DATA!B3 -> cout | C2: =DATA!C3 -> cout | D2: =DATA!D3 -> benefice | E2: =DATA!E3 -> benefice | F2: =DATA!F3 -> benefice | G2: =DATA!G3 -> benefice | H2: =DATA!H3 -> benefice | I2: =DATA!I3 -> cout | J2: =DATA!J3 -> cout | AA2: Virer elongation des critères ou mettre en contrainte plutôt et checker les besoins, limites pour uen pièce.
A3: Alternative | B3: EF Single score | C3: Density (g/cm³) | D3: Tensile Modulus (GPa) | E3: Tensile Strength (MPa) | F3: Elongation at break (%) | G3: Flexural modulus (GPa) | H3: Flexural strength (MPa) | I3: CTE (µm/m·°C) | J3: Raw material cost (€/kg)
A4: Poids | B4: =DATA!B7 -> 0.10360018 | C4: =DATA!C7 -> 0.10681275 | D4: =DATA!D7 -> 0.079132717 | E4: =DATA!E7 -> 0.097058973 | F4: =DATA!F7 -> 0.10913698 | G4: =DATA!G7 -> 0.077157486 | H4: =DATA!H7 -> 0.087306732 | I4: =DATA!I7 -> 0.22601941 | J4: =DATA!J7 -> 0.11377476 | K4: =SUM(B4:J4) -> 1 | L4: Normalisation R | U4: Pondération V
L5: R: EF | M5: R: Density | N5: R: E | O5: R: σt | P5: R: εt | Q5: R: Eflex | R5: R: σflex | S5: R: CTE | T5: R: Cost | U5: V: EF | V5: V: Density | W5: V: E | X5: V: σt | Y5: V: εt | Z5: V: Eflex | AA5: V: σflex | AB5: V: CTE | AC5: V: Cost | AD5: S+ (distance à A+) | AE5: S- (distance à A-) | AF5: Score C = S-/(S++S-) | AH5: Classement automatique | AI5: Score C | AJ5: Rang
A6: =IF(DATA!A8="","",DATA!A8) -> Flax/Epoxy | B6: =IF(DATA!B8="","",DATA!B8) -> 0.59 | C6: =IF(DATA!C8="","",DATA!C8) -> 1.35 | D6: =IF(DATA!D8="","",DATA!D8) -> 35 | E6: =IF(DATA!E8="","",DATA!E8) -> 610 | F6: =IF(DATA!F8="","",DATA!F8) -> 1.8 | G6: =IF(DATA!G8="","",DATA!G8) -> 39 | H6: =IF(DATA!H8="","",DATA!H8) -> 520 | ... J6: =IF(DATA!J8="","",DATA!J8) -> 3.8 | L6: =IF(B6="","",B6/SQRT(SUMSQ(B$6:B$105))) -> 0.10892118 | M6: =IF(C6="","",C6/SQRT(SUMSQ(C$6:C$105))) -> 0.15076037 | N6: =IF(D6="","",D6/SQRT(SUMSQ(D$6:D$105))) -> 0.13938472 | O6: =IF(E6="","",E6/SQRT(SUMSQ(E$6:E$105))) -> 0.22795849 | P6: =IF(F6="","",F6/SQRT(SUMSQ(F$6:F$105))) -> 0.044610487 | Q6: =IF(G6="","",G6/SQRT(SUMSQ(G$6:G$105))) -> 0.15020122 | R6: =IF(H6="","",H6/SQRT(SUMSQ(H$6:H$105))) -> 0.21957744 | S6: =IF(I6="","",I6/SQRT(SUMSQ(I$6:I$105))) -> 0.31714563 | T6: =IF(J6="","",J6/SQRT(SUMSQ(J$6:J$105))) -> 0.16033755 | U6: =IF(L6="","",L6*$B$4) -> 0.011284254 | V6: =IF(M6="","",M6*$C$4) -> 0.016103129 | W6: =IF(N6="","",N6*$D$4) -> 0.011029892 | X6: =IF(O6="","",O6*$E$4) -> 0.022125417 | Y6: =IF(P6="","",P6*$F$4) -> 0.004868654 | Z6: =IF(Q6="","",Q6*$G$4) -> 0.011589148 | AA6: =IF(R6="","",R6*$H$4) -> 0.019170589 | AB6: =IF(S6="","",S6*$I$4) -> 0.071681069 | AC6: =IF(T6="","",T6*$J$4) -> 0.018242367 | AD6: {=IF(SUM(U6:AC6)=0,"",SQRT(SUMPRODUCT((U6:AC6-U$113:AC$113)*(U6:AC6-U$113:AC$113))))} -> 0.17794024 | AE6: {=IF(SUM(U6:AC6)=0,"",SQRT(SUMPRODUCT((U6:AC6-U$114:AC$114)*(U6:AC6-U$114:AC$114))))} -> 0.1514138 | AF6: =IF(OR(AD6="",AE6=""),"",AE6/(AD6+AE6)) -> 0.45972959 | AH6: {=IFERROR(_xlfn.SORTBY(_xlfn._xlws.FILTER(A6:A105,A6:A105<>""), _xlfn._xlws.FILTER(AF6:AF105,A6:A105<>""), -1), "")} -> Hemp/Epoxy | AI6: {=IFERROR(_xlfn._xlws.SORT(_xlfn._xlws.FILTER(AF6:AF105,A6:A105<>""), 1, -1), "")} -> 0.73113089 | AJ6: {=IF(AH6="","",_xlfn.SEQUENCE(COUNTA(_xlfn._xlws.FILTER(A6:A105,A6:A105<>""))))} -> 1
A7: =IF(DATA!A9="","",DATA!A9) -> Carbon/Epoxy | B7: =IF(DATA!B9="","",DATA!B9) -> 4.98 | C7: =IF(DATA!C9="","",DATA!C9) -> 1.42 | D7: =IF(DATA!D9="","",DATA!D9) -> 120 | E7: =IF(DATA!E9="","",DATA!E9) -> 2135 | F7: =IF(DATA!F9="","",DATA!F9) -> 1.15 | G7: =IF(DATA!G9="","",DATA!G9) -> 134 | H7: =IF(DATA!H9="","",DATA!H9) -> 1815 | ... J7: =IF(DATA!J9="","",DATA!J9) -> 20 | L7: =IF(B7="","",B7/SQRT(SUMSQ(B$6:B$105))) -> 0.9193686 | M7: =IF(C7="","",C7/SQRT(SUMSQ(C$6:C$105))) -> 0.15857758 | N7: =IF(D7="","",D7/SQRT(SUMSQ(D$6:D$105))) -> 0.47789047 | O7: =IF(E7="","",E7/SQRT(SUMSQ(E$6:E$105))) -> 0.7978547 | P7: =IF(F7="","",F7/SQRT(SUMSQ(F$6:F$105))) -> 0.028501145 | Q7: =IF(G7="","",G7/SQRT(SUMSQ(G$6:G$105))) -> 0.51607598 | R7: =IF(H7="","",H7/SQRT(SUMSQ(H$6:H$105))) -> 0.76640973 | S7: =IF(I7="","",I7/SQRT(SUMSQ(I$6:I$105))) -> 0.047254699 | T7: =IF(J7="","",J7/SQRT(SUMSQ(J$6:J$105))) -> 0.84388186 | U7: =IF(L7="","",L7*$B$4) -> 0.095246757 | V7: =IF(M7="","",M7*$C$4) -> 0.016938106 | W7: =IF(N7="","",N7*$D$4) -> 0.037816771 | X7: =IF(O7="","",O7*$E$4) -> 0.077438958 | Y7: =IF(P7="","",P7*$F$4) -> 0.0031105289 | Z7: =IF(Q7="","",Q7*$G$4) -> 0.039819125 | AA7: =IF(R7="","",R7*$H$4) -> 0.066912729 | AB7: =IF(S7="","",S7*$I$4) -> 0.010680479 | AC7: =IF(T7="","",T7*$J$4) -> 0.09601246 | AD7: {=IF(SUM(U7:AC7)=0,"",SQRT(SUMPRODUCT((U7:AC7-U$113:AC$113)*(U7:AC7-U$113:AC$113))))} -> 0.17399991 | AE7: {=IF(SUM(U7:AC7)=0,"",SQRT(SUMPRODUCT((U7:AC7-U$114:AC$114)*(U7:AC7-U$114:AC$114))))} -> 0.1711111 | AF7: =IF(OR(AD7="",AE7=""),"",AE7/(AD7+AE7)) -> 0.49581467 | AH7: Jute/epoxy | AI7: 0.72047065 | AJ7: 2
A8: =IF(DATA!A10="","",DATA!A10) -> Glass/Epoxy | B8: =IF(DATA!B10="","",DATA!B10) -> 0.69 | C8: =IF(DATA!C10="","",DATA!C10) -> 1.8 | D8: =IF(DATA!D10="","",DATA!D10) -> 40 | E8: =IF(DATA!E10="","",DATA!E10) -> 1135 | F8: =IF(DATA!F10="","",DATA!F10) -> 1.3 | G8: =IF(DATA!G10="","",DATA!G10) -> 43 | H8: =IF(DATA!H10="","",DATA!H10) -> 965 | ... J8: =IF(DATA!J10="","",DATA!J10) -> 4 | L8: =IF(B8="","",B8/SQRT(SUMSQ(B$6:B$105))) -> 0.1273824 | M8: =IF(C8="","",C8/SQRT(SUMSQ(C$6:C$105))) -> 0.20101383 | N8: =IF(D8="","",D8/SQRT(SUMSQ(D$6:D$105))) -> 0.15929682 | O8: =IF(E8="","",E8/SQRT(SUMSQ(E$6:E$105))) -> 0.42415227 | P8: =IF(F8="","",F8/SQRT(SUMSQ(F$6:F$105))) -> 0.032218685 | Q8: =IF(G8="","",G8/SQRT(SUMSQ(G$6:G$105))) -> 0.16560647 | R8: =IF(H8="","",H8/SQRT(SUMSQ(H$6:H$105))) -> 0.40748506 | S8: =IF(I8="","",I8/SQRT(SUMSQ(I$6:I$105))) -> 0.55500485 | T8: =IF(J8="","",J8/SQRT(SUMSQ(J$6:J$105))) -> 0.16877637 | U8: =IF(L8="","",L8*$B$4) -> 0.01319684 | V8: =IF(M8="","",M8*$C$4) -> 0.021470839 | W8: =IF(N8="","",N8*$D$4) -> 0.01260559 | X8: =IF(O8="","",O8*$E$4) -> 0.041167783 | Y8: =IF(P8="","",P8*$F$4) -> 0.0035162501 | Z8: =IF(Q8="","",Q8*$G$4) -> 0.012777779 | AA8: =IF(R8="","",R8*$H$4) -> 0.035576189 | AB8: =IF(S8="","",S8*$I$4) -> 0.12544187 | AC8: =IF(T8="","",T8*$J$4) -> 0.019202492 | AD8: {=IF(SUM(U8:AC8)=0,"",SQRT(SUMPRODUCT((U8:AC8-U$113:AC$113)*(U8:AC8-U$113:AC$113))))} -> 0.19490225 | AE8: {=IF(SUM(U8:AC8)=0,"",SQRT(SUMPRODUCT((U8:AC8-U$114:AC$114)*(U8:AC8-U$114:AC$114))))} -> 0.14144639 | AF8: =IF(OR(AD8="",AE8=""),"",AE8/(AD8+AE8)) -> 0.42053504 | AH8: Chromium steel template | AI8: 0.52144013 | AJ8: 3
A9: =IF(DATA!A11="","",DATA!A11) -> Aluminium template | B9: =IF(DATA!B11="","",DATA!B11) -> 1.58 | C9: =IF(DATA!C11="","",DATA!C11) -> 2.7 | D9: =IF(DATA!D11="","",DATA!D11) -> 70 | E9: =IF(DATA!E11="","",DATA!E11) -> 330 | F9: =IF(DATA!F11="","",DATA!F11) -> 3.4 | G9: =IF(DATA!G11="","",DATA!G11) -> 70 | H9: =IF(DATA!H11="","",DATA!H11) -> 325 | ... J9: =IF(DATA!J11="","",DATA!J11) -> 10 | L9: =IF(B9="","",B9/SQRT(SUMSQ(B$6:B$105))) -> 0.29168723 | M9: =IF(C9="","",C9/SQRT(SUMSQ(C$6:C$105))) -> 0.30152074 | N9: =IF(D9="","",D9/SQRT(SUMSQ(D$6:D$105))) -> 0.27876944 | O9: =IF(E9="","",E9/SQRT(SUMSQ(E$6:E$105))) -> 0.1233218 | P9: =IF(F9="","",F9/SQRT(SUMSQ(F$6:F$105))) -> 0.084264254 | Q9: =IF(G9="","",G9/SQRT(SUMSQ(G$6:G$105))) -> 0.26959193 | R9: =IF(H9="","",H9/SQRT(SUMSQ(H$6:H$105))) -> 0.1372359 | S9: =IF(I9="","",I9/SQRT(SUMSQ(I$6:I$105))) -> 0.36471747 | T9: =IF(J9="","",J9/SQRT(SUMSQ(J$6:J$105))) -> 0.42194093 | U9: =IF(L9="","",L9*$B$4) -> 0.030218851 | V9: =IF(M9="","",M9*$C$4) -> 0.032206259 | W9: =IF(N9="","",N9*$D$4) -> 0.022059783 | X9: =IF(O9="","",O9*$E$4) -> 0.011969488 | Y9: =IF(P9="","",P9*$F$4) -> 0.0091963464 | Z9: =IF(Q9="","",Q9*$G$4) -> 0.020801036 | AA9: =IF(R9="","",R9*$H$4) -> 0.011981618 | AB9: =IF(S9="","",S9*$I$4) -> 0.08243323 | AC9: =IF(T9="","",T9*$J$4) -> 0.04800623 | AD9: {=IF(SUM(U9:AC9)=0,"",SQRT(SUMPRODUCT((U9:AC9-U$113:AC$113)*(U9:AC9-U$113:AC$113))))} -> 0.18217786 | AE9: {=IF(SUM(U9:AC9)=0,"",SQRT(SUMPRODUCT((U9:AC9-U$114:AC$114)*(U9:AC9-U$114:AC$114))))} -> 0.11517282 | AF9: =IF(OR(AD9="",AE9=""),"",AE9/(AD9+AE9)) -> 0.38732994 | AH9: Carbon/Epoxy | AI9: 0.49581467 | AJ9: 4
A10: =IF(DATA!A12="","",DATA!A12) -> Chromium steel template | B10: =IF(DATA!B12="","",DATA!B12) -> 0.77 | C10: =IF(DATA!C12="","",DATA!C12) -> 7.9 | D10: =IF(DATA!D12="","",DATA!D12) -> 200 | E10: =IF(DATA!E12="","",DATA!E12) -> 750 | F10: =IF(DATA!F12="","",DATA!F12) -> 40 | G10: =IF(DATA!G12="","",DATA!G12) -> 200 | H10: =IF(DATA!H12="","",DATA!H12) -> 900 | ... J10: =IF(DATA!J12="","",DATA!J12) -> 2.5 | L10: =IF(B10="","",B10/SQRT(SUMSQ(B$6:B$105))) -> 0.14215137 | M10: =IF(C10="","",C10/SQRT(SUMSQ(C$6:C$105))) -> 0.88222736 | N10: =IF(D10="","",D10/SQRT(SUMSQ(D$6:D$105))) -> 0.79648411 | O10: =IF(E10="","",E10/SQRT(SUMSQ(E$6:E$105))) -> 0.28027683 | P10: =IF(F10="","",F10/SQRT(SUMSQ(F$6:F$105))) -> 0.99134417 | Q10: =IF(G10="","",G10/SQRT(SUMSQ(G$6:G$105))) -> 0.77026266 | R10: =IF(H10="","",H10/SQRT(SUMSQ(H$6:H$105))) -> 0.38003788 | S10: =IF(I10="","",I10/SQRT(SUMSQ(I$6:I$105))) -> 0.26957378 | T10: =IF(J10="","",J10/SQRT(SUMSQ(J$6:J$105))) -> 0.10548523 | U10: =IF(L10="","",L10*DATA!B4) -> 0.015794439 | V10: =IF(M10="","",M10*DATA!C4) -> 0.098024282 | W10: =IF(N10="","",N10*DATA!D4) -> 0.08849735 | X10: =IF(O10="","",O10*DATA!E4) -> 0.031141558 | Y10: =IF(P10="","",P10*DATA!F4) -> 0.11014825 | Z10: =IF(Q10="","",Q10*DATA!G4) -> 0.085583884 | AA10: =IF(R10="","",R10*DATA!H4) -> 0.042226009 | AB10: =IF(S10="","",S10*DATA!I4) -> 0.029952343 | AC10: =IF(T10="","",T10*DATA!J4) -> 0.011720464 | AD10: =IF(U10="","",SQRT(SUMPRODUCT((U10:AC10-U116:AC116)^2))) -> 0.20232298 | AE10: {=IF(U10="","",SQRT(SUMPRODUCT((U10:AC10-U114:AC114)^2)))} -> 0.22045167 | AF10: =IF(OR(AD10="",AE10=""),"",AE10/(AD10+AE10)) -> 0.52144013 | AH10: Flax/Epoxy | AI10: 0.45972959 | AJ10: 5
A11: =IF(DATA!A13="","",DATA!A13) -> Hemp/Epoxy | B11: =IF(DATA!B13="","",DATA!B13) -> 0.55 | C11: =IF(DATA!C13="","",DATA!C13) -> 1.31 | D11: =IF(DATA!D13="","",DATA!D13) -> 28 | E11: =IF(DATA!E13="","",DATA!E13) -> 398 | F11: =IF(DATA!F13="","",DATA!F13) -> 2 | G11: =IF(DATA!G13="","",DATA!G13) -> 32 | H11: =IF(DATA!H13="","",DATA!H13) -> 340 | ... J11: =IF(DATA!J13="","",DATA!J13) -> 4 | L11: =IF(B11="","",B11/SQRT(SUMSQ(B$6:B$105))) -> 0.10153669 | M11: =IF(C11="","",C11/SQRT(SUMSQ(C$6:C$105))) -> 0.1462934 | N11: =IF(D11="","",D11/SQRT(SUMSQ(D$6:D$105))) -> 0.11150778 | O11: =IF(E11="","",E11/SQRT(SUMSQ(E$6:E$105))) -> 0.14873357 | P11: =IF(F11="","",F11/SQRT(SUMSQ(F$6:F$105))) -> 0.049567208 | Q11: =IF(G11="","",G11/SQRT(SUMSQ(G$6:G$105))) -> 0.12324202 | R11: =IF(H11="","",H11/SQRT(SUMSQ(H$6:H$105))) -> 0.14356987 | S11: =IF(I11="","",I11/SQRT(SUMSQ(I$6:I$105))) -> 0.39643204 | T11: =IF(J11="","",J11/SQRT(SUMSQ(J$6:J$105))) -> 0.16877637 | U11: =IF(L11="","",L11*DATA!B4) -> 0.011281742 | V11: =IF(M11="","",M11*DATA!C4) -> 0.01625466 | W11: =IF(N11="","",N11*DATA!D4) -> 0.012389629 | X11: =IF(O11="","",O11*DATA!E4) -> 0.016525787 | Y11: =IF(P11="","",P11*DATA!F4) -> 0.0055074125 | Z11: =IF(Q11="","",Q11*DATA!G4) -> 0.013693421 | AA11: =IF(R11="","",R11*DATA!H4) -> 0.015952048 | AB11: =IF(S11="","",S11*DATA!I4) -> 0.044047564 | AC11: =IF(T11="","",T11*DATA!J4) -> 0.018752743 | AD11: =IF(U11="","",SQRT(SUMPRODUCT((U11:AC11-U117:AC117)^2))) -> 0.059851973 | AE11: =IF(U11="","",SQRT(SUMPRODUCT((U11:AC11-U114:AC114)^2))) -> 0.16275438 | AF11: =IF(OR(AD11="",AE11=""),"",AE11/(AD11+AE11)) -> 0.73113089 | AH11: Glass/Epoxy | AI11: 0.42053504 | AJ11: 6
A12: =IF(DATA!A14="","",DATA!A14) -> Jute/epoxy | B12: =IF(DATA!B14="","",DATA!B14) -> 0.57 | C12: =IF(DATA!C14="","",DATA!C14) -> 1.3 | D12: =IF(DATA!D14="","",DATA!D14) -> 12 | E12: =IF(DATA!E14="","",DATA!E14) -> 335 | F12: =IF(DATA!F14="","",DATA!F14) -> 2.5 | G12: =IF(DATA!G14="","",DATA!G14) -> 13 | H12: =IF(DATA!H14="","",DATA!H14) -> 285 | ... J12: =IF(DATA!J14="","",DATA!J14) -> 3 | L12: =IF(B12="","",B12/SQRT(SUMSQ(B$6:B$105))) -> 0.10522894 | M12: =IF(C12="","",C12/SQRT(SUMSQ(C$6:C$105))) -> 0.14517665 | N12: =IF(D12="","",D12/SQRT(SUMSQ(D$6:D$105))) -> 0.047789047 | O12: =IF(E12="","",E12/SQRT(SUMSQ(E$6:E$105))) -> 0.12519032 | P12: =IF(F12="","",F12/SQRT(SUMSQ(F$6:F$105))) -> 0.06195901 | Q12: =IF(G12="","",G12/SQRT(SUMSQ(G$6:G$105))) -> 0.050067073 | R12: =IF(H12="","",H12/SQRT(SUMSQ(H$6:H$105))) -> 0.12034533 | S12: =IF(I12="","",I12/SQRT(SUMSQ(I$6:I$105))) -> 0.47571844 | T12: =IF(J12="","",J12/SQRT(SUMSQ(J$6:J$105))) -> 0.12658228 | U12: =IF(L12="","",L12*DATA!B4) -> 0.011691987 | V12: =IF(M12="","",M12*DATA!C4) -> 0.016130578 | W12: =IF(N12="","",N12*DATA!D4) -> 0.005309841 | X12: =IF(O12="","",O12*DATA!E4) -> 0.013909896 | Y12: =IF(P12="","",P12*DATA!F4) -> 0.0068842656 | Z12: =IF(Q12="","",Q12*DATA!G4) -> 0.0055629524 | AA12: =IF(R12="","",R12*DATA!H4) -> 0.01337157 | AB12: =IF(S12="","",S12*DATA!I4) -> 0.052857076 | AC12: =IF(T12="","",T12*DATA!J4) -> 0.014064557 | AD12: =IF(U12="","",SQRT(SUMPRODUCT((U12:AC12-U118:AC118)^2))) -> 0.062188411 | AE12: =IF(U12="","",SQRT(SUMPRODUCT((U12:AC12-U114:AC114)^2))) -> 0.16028702 | AF12: =IF(OR(AD12="",AE12=""),"",AE12/(AD12+AE12)) -> 0.72047065 | AH12: Aluminium template | AI12: 0.38732994 | AJ12: 7
A13: =IF(DATA!A15="","",DATA!A15) | B13: =IF(DATA!B15="","",DATA!B15) | C13: =IF(DATA!C15="","",DATA!C15) | D13: =IF(DATA!D15="","",DATA!D15) | E13: =IF(DATA!E15="","",DATA!E15) | F13: =IF(DATA!F15="","",DATA!F15) | G13: =IF(DATA!G15="","",DATA!G15) | H13: =IF(DATA!H15="","",DATA!H15) | ... J13: =IF(DATA!J15="","",DATA!J15) | L13: =IF(B13="","",B13/SQRT(SUMSQ(B$6:B$105))) | M13: =IF(C13="","",C13/SQRT(SUMSQ(C$6:C$105))) | N13: =IF(D13="","",D13/SQRT(SUMSQ(D$6:D$105))) | O13: =IF(E13="","",E13/SQRT(SUMSQ(E$6:E$105))) | P13: =IF(F13="","",F13/SQRT(SUMSQ(F$6:F$105))) | Q13: =IF(G13="","",G13/SQRT(SUMSQ(G$6:G$105))) | R13: =IF(H13="","",H13/SQRT(SUMSQ(H$6:H$105))) | S13: =IF(I13="","",I13/SQRT(SUMSQ(I$6:I$105))) | T13: =IF(J13="","",J13/SQRT(SUMSQ(J$6:J$105))) | U13: =IF(L13="","",L13*DATA!B4) | V13: =IF(M13="","",M13*DATA!C4) | W13: =IF(N13="","",N13*DATA!D4) | X13: =IF(O13="","",O13*DATA!E4) | Y13: =IF(P13="","",P13*DATA!F4) | Z13: =IF(Q13="","",Q13*DATA!G4) | AA13: =IF(R13="","",R13*DATA!H4) | AB13: =IF(S13="","",S13*DATA!I4) | AC13: =IF(T13="","",T13*DATA!J4) | AD13: =IF(U13="","",SQRT(SUMPRODUCT((U13:AC13-U119:AC119)^2))) | AE13: =IF(U13="","",SQRT(SUMPRODUCT((U13:AC13-U114:AC114)^2))) | AF13: =IF(OR(AD13="",AE13=""),"",AE13/(AD13+AE13))
A14: =IF(DATA!A16="","",DATA!A16) | B14: =IF(DATA!B16="","",DATA!B16) | C14: =IF(DATA!C16="","",DATA!C16) | D14: =IF(DATA!D16="","",DATA!D16) | E14: =IF(DATA!E16="","",DATA!E16) | F14: =IF(DATA!F16="","",DATA!F16) | G14: =IF(DATA!G16="","",DATA!G16) | H14: =IF(DATA!H16="","",DATA!H16) | ... J14: =IF(DATA!J16="","",DATA!J16) | L14: =IF(B14="","",B14/SQRT(SUMSQ(B$6:B$105))) | M14: =IF(C14="","",C14/SQRT(SUMSQ(C$6:C$105))) | N14: =IF(D14="","",D14/SQRT(SUMSQ(D$6:D$105))) | O14: =IF(E14="","",E14/SQRT(SUMSQ(E$6:E$105))) | P14: =IF(F14="","",F14/SQRT(SUMSQ(F$6:F$105))) | Q14: =IF(G14="","",G14/SQRT(SUMSQ(G$6:G$105))) | R14: =IF(H14="","",H14/SQRT(SUMSQ(H$6:H$105))) | S14: =IF(I14="","",I14/SQRT(SUMSQ(I$6:I$105))) | T14: =IF(J14="","",J14/SQRT(SUMSQ(J$6:J$105))) | U14: =IF(L14="","",L14*DATA!B4) | V14: =IF(M14="","",M14*DATA!C4) | W14: =IF(N14="","",N14*DATA!D4) | X14: =IF(O14="","",O14*DATA!E4) | Y14: =IF(P14="","",P14*DATA!F4) | Z14: =IF(Q14="","",Q14*DATA!G4) | AA14: =IF(R14="","",R14*DATA!H4) | AB14: =IF(S14="","",S14*DATA!I4) | AC14: =IF(T14="","",T14*DATA!J4) | AD14: =IF(U14="","",SQRT(SUMPRODUCT((U14:AC14-U120:AC120)^2))) | AE14: =IF(U14="","",SQRT(SUMPRODUCT((U14:AC14-U114:AC114)^2))) | AF14: =IF(OR(AD14="",AE14=""),"",AE14/(AD14+AE14))
A15: =IF(DATA!A17="","",DATA!A17) | B15: =IF(DATA!B17="","",DATA!B17) | C15: =IF(DATA!C17="","",DATA!C17) | D15: =IF(DATA!D17="","",DATA!D17) | E15: =IF(DATA!E17="","",DATA!E17) | F15: =IF(DATA!F17="","",DATA!F17) | G15: =IF(DATA!G17="","",DATA!G17) | H15: =IF(DATA!H17="","",DATA!H17) | ... J15: =IF(DATA!J17="","",DATA!J17) | L15: =IF(B15="","",B15/SQRT(SUMSQ(B$6:B$105))) | M15: =IF(C15="","",C15/SQRT(SUMSQ(C$6:C$105))) | N15: =IF(D15="","",D15/SQRT(SUMSQ(D$6:D$105))) | O15: =IF(E15="","",E15/SQRT(SUMSQ(E$6:E$105))) | P15: =IF(F15="","",F15/SQRT(SUMSQ(F$6:F$105))) | Q15: =IF(G15="","",G15/SQRT(SUMSQ(G$6:G$105))) | R15: =IF(H15="","",H15/SQRT(SUMSQ(H$6:H$105))) | S15: =IF(I15="","",I15/SQRT(SUMSQ(I$6:I$105))) | T15: =IF(J15="","",J15/SQRT(SUMSQ(J$6:J$105))) | U15: =IF(L15="","",L15*DATA!B6) | V15: =IF(M15="","",M15*DATA!C4) | W15: =IF(N15="","",N15*DATA!D4) | X15: =IF(O15="","",O15*DATA!E4) | Y15: =IF(P15="","",P15*DATA!F4) | Z15: =IF(Q15="","",Q15*DATA!G4) | AA15: =IF(R15="","",R15*DATA!H4) | AB15: =IF(S15="","",S15*DATA!I4) | AC15: =IF(T15="","",T15*DATA!J4) | AD15: =IF(U15="","",SQRT(SUMPRODUCT((U15:AC15-U121:AC121)^2))) | AE15: =IF(U15="","",SQRT(SUMPRODUCT((U15:AC15-U114:AC114)^2))) | AF15: =IF(OR(AD15="",AE15=""),"",AE15/(AD15+AE15))
A16: =IF(DATA!A18="","",DATA!A18) | B16: =IF(DATA!B18="","",DATA!B18) | H16: =IF(DATA!H18="","",DATA!H18) | I16: =IF(DATA!I18="","",DATA!I18) | J16: =IF(DATA!J18="","",DATA!J18) | L16: =IF(B16="","",B16/SQRT(SUMSQ(B$6:B$105))) | M16: =IF(C16="","",C16/SQRT(SUMSQ(C$6:C$105))) | N16: =IF(D16="","",D16/SQRT(SUMSQ(D$6:D$105))) | O16: =IF(E16="","",E16/SQRT(SUMSQ(E$6:E$105))) | P16: =IF(F16="","",F16/SQRT(SUMSQ(F$6:F$105))) | Q16: =IF(G16="","",G16/SQRT(SUMSQ(G$6:G$105))) | R16: =IF(H16="","",H16/SQRT(SUMSQ(H$6:H$105))) | S16: =IF(I16="","",I16/SQRT(SUMSQ(I$6:I$105))) | T16: =IF(J16="","",J16/SQRT(SUMSQ(J$6:J$105))) | U16: =IF(L16="","",L16*DATA!B8) | V16: =IF(M16="","",M16*DATA!C4) | W16: =IF(N16="","",N16*DATA!D4) | X16: =IF(O16="","",O16*DATA!E4) | Y16: =IF(P16="","",P16*DATA!F4) | Z16: =IF(Q16="","",Q16*DATA!G4) | AA16: =IF(R16="","",R16*DATA!H4) | AB16: =IF(S16="","",S16*DATA!I4) | AC16: =IF(T16="","",T16*DATA!J4) | AD16: =IF(U16="","",SQRT(SUMPRODUCT((U16:AC16-U122:AC122)^2))) | AE16: =IF(U16="","",SQRT(SUMPRODUCT((U16:AC16-U114:AC114)^2))) | AF16: =IF(OR(AD16="",AE16=""),"",AE16/(AD16+AE16))
A17: =IF(DATA!A19="","",DATA!A19) | B17: =IF(DATA!B19="","",DATA!B19) | H17: =IF(DATA!H19="","",DATA!H19) | I17: =IF(DATA!I19="","",DATA!I19) | J17: =IF(DATA!J19="","",DATA!J19) | L17: =IF(B17="","",B17/SQRT(SUMSQ(B$6:B$105))) | M17: =IF(C17="","",C17/SQRT(SUMSQ(C$6:C$105))) | N17: =IF(D17="","",D17/SQRT(SUMSQ(D$6:D$105))) | O17: =IF(E17="","",E17/SQRT(SUMSQ(E$6:E$105))) | P17: =IF(F17="","",F17/SQRT(SUMSQ(F$6:F$105))) | Q17: =IF(G17="","",G17/SQRT(SUMSQ(G$6:G$105))) | R17: =IF(H17="","",H17/SQRT(SUMSQ(H$6:H$105))) | S17: =IF(I17="","",I17/SQRT(SUMSQ(I$6:I$105))) | T17: =IF(J17="","",J17/SQRT(SUMSQ(J$6:J$105))) | U17: =IF(L17="","",L17*DATA!B9) | V17: =IF(M17="","",M17*DATA!C4) | W17: =IF(N17="","",N17*DATA!D4) | X17: =IF(O17="","",O17*DATA!E4) | Y17: =IF(P17="","",P17*DATA!F4) | Z17: =IF(Q17="","",Q17*DATA!G4) | AA17: =IF(R17="","",R17*DATA!H4) | AB17: =IF(S17="","",S17*DATA!I4) | AC17: =IF(T17="","",T17*DATA!J4) | AD17: =IF(U17="","",SQRT(SUMPRODUCT((U17:AC17-U123:AC123)^2))) | AE17: =IF(U17="","",SQRT(SUMPRODUCT((U17:AC17-U114:AC114)^2))) | AF17: =IF(OR(AD17="",AE17=""),"",AE17/(AD17+AE17))
A18: =IF(DATA!A20="","",DATA!A20) | B18: =IF(DATA!B20="","",DATA!B20) | H18: =IF(DATA!H20="","",DATA!H20) | I18: =IF(DATA!I20="","",DATA!I20) | J18: =IF(DATA!J20="","",DATA!J20) | L18: =IF(B18="","",B18/SQRT(SUMSQ(B$6:B$105))) | M18: =IF(C18="","",C18/SQRT(SUMSQ(C$6:C$105))) | N18: =IF(D18="","",D18/SQRT(SUMSQ(D$6:D$105))) | O18: =IF(E18="","",E18/SQRT(SUMSQ(E$6:E$105))) | P18: =IF(F18="","",F18/SQRT(SUMSQ(F$6:F$105))) | Q18: =IF(G18="","",G18/SQRT(SUMSQ(G$6:G$105))) | R18: =IF(H18="","",H18/SQRT(SUMSQ(H$6:H$105))) | S18: =IF(I18="","",I18/SQRT(SUMSQ(I$6:I$105))) | T18: =IF(J18="","",J18/SQRT(SUMSQ(J$6:J$105))) | U18: =IF(L18="","",L18*DATA!B10) | V18: =IF(M18="","",M18*DATA!C4) | W18: =IF(N18="","",N18*DATA!D4) | X18: =IF(O18="","",O18*DATA!E4) | Y18: =IF(P18="","",P18*DATA!F4) | Z18: =IF(Q18="","",Q18*DATA!G4) | AA18: =IF(R18="","",R18*DATA!H4) | AB18: =IF(S18="","",S18*DATA!I4) | AC18: =IF(T18="","",T18*DATA!J4) | AD18: =IF(U18="","",SQRT(SUMPRODUCT((U18:AC18-U124:AC124)^2))) | AE18: =IF(U18="","",SQRT(SUMPRODUCT((U18:AC18-U114:AC114)^2))) | AF18: =IF(OR(AD18="",AE18=""),"",AE18/(AD18+AE18))
A19: =IF(DATA!A21="","",DATA!A21) | B19: =IF(DATA!B21="","",DATA!B21) | H19: =IF(DATA!H21="","",DATA!H21) | I19: =IF(DATA!I21="","",DATA!I21) | J19: =IF(DATA!J21="","",DATA!J21) | L19: =IF(B19="","",B19/SQRT(SUMSQ(B$6:B$105))) | M19: =IF(C19="","",C19/SQRT(SUMSQ(C$6:C$105))) | N19: =IF(D19="","",D19/SQRT(SUMSQ(D$6:D$105))) | O19: =IF(E19="","",E19/SQRT(SUMSQ(E$6:E$105))) | P19: =IF(F19="","",F19/SQRT(SUMSQ(F$6:F$105))) | Q19: =IF(G19="","",G19/SQRT(SUMSQ(G$6:G$105))) | R19: =IF(H19="","",H19/SQRT(SUMSQ(H$6:H$105))) | S19: =IF(I19="","",I19/SQRT(SUMSQ(I$6:I$105))) | T19: =IF(J19="","",J19/SQRT(SUMSQ(J$6:J$105))) | U19: =IF(L19="","",L19*DATA!B11) | V19: =IF(M19="","",M19*DATA!C4) | W19: =IF(N19="","",N19*DATA!D4) | X19: =IF(O19="","",O19*DATA!E4) | Y19: =IF(P19="","",P19*DATA!F4) | Z19: =IF(Q19="","",Q19*DATA!G4) | AA19: =IF(R19="","",R19*DATA!H4) | AB19: =IF(S19="","",S19*DATA!I4) | AC19: =IF(T19="","",T19*DATA!J4) | AD19: =IF(U19="","",SQRT(SUMPRODUCT((U19:AC19-U125:AC125)^2))) | AE19: =IF(U19="","",SQRT(SUMPRODUCT((U19:AC19-U114:AC114)^2))) | AF19: =IF(OR(AD19="",AE19=""),"",AE19/(AD19+AE19))
A20: =IF(DATA!A22="","",DATA!A22) | B20: =IF(DATA!B22="","",DATA!B22) | H20: =IF(DATA!H22="","",DATA!H22) | I20: =IF(DATA!I22="","",DATA!I22) | J20: =IF(DATA!J22="","",DATA!J22) | L20: =IF(B20="","",B20/SQRT(SUMSQ(B$6:B$105))) | M20: =IF(C20="","",C20/SQRT(SUMSQ(C$6:C$105))) | N20: =IF(D20="","",D20/SQRT(SUMSQ(D$6:D$105))) | O20: =IF(E20="","",E20/SQRT(SUMSQ(E$6:E$105))) | P20: =IF(F20="","",F20/SQRT(SUMSQ(F$6:F$105))) | Q20: =IF(G20="","",G20/SQRT(SUMSQ(G$6:G$105))) | R20: =IF(H20="","",H20/SQRT(SUMSQ(H$6:H$105))) | S20: =IF(I20="","",I20/SQRT(SUMSQ(I$6:I$105))) | T20: =IF(J20="","",J20/SQRT(SUMSQ(J$6:J$105))) | U20: =IF(L20="","",L20*DATA!B12) | V20: =IF(M20="","",M20*DATA!C4) | W20: =IF(N20="","",N20*DATA!D4) | X20: =IF(O20="","",O20*DATA!E4) | Y20: =IF(P20="","",P20*DATA!F4) | Z20: =IF(Q20="","",Q20*DATA!G4) | AA20: =IF(R20="","",R20*DATA!H4) | AB20: =IF(S20="","",S20*DATA!I4) | AC20: =IF(T20="","",T20*DATA!J4) | AD20: =IF(U20="","",SQRT(SUMPRODUCT((U20:AC20-U126:AC126)^2))) | AE20: =IF(U20="","",SQRT(SUMPRODUCT((U20:AC20-U114:AC114)^2))) | AF20: =IF(OR(AD20="",AE20=""),"",AE20/(AD20+AE20))
A21: =IF(DATA!A23="","",DATA!A23) | B21: =IF(DATA!B23="","",DATA!B23) | H21: =IF(DATA!H23="","",DATA!H23) | I21: =IF(DATA!I23="","",DATA!I23) | J21: =IF(DATA!J23="","",DATA!J23) | L21: =IF(B21="","",B21/SQRT(SUMSQ(B$6:B$105))) | M21: =IF(C21="","",C21/SQRT(SUMSQ(C$6:C$105))) | N21: =IF(D21="","",D21/SQRT(SUMSQ(D$6:D$105))) | O21: =IF(E21="","",E21/SQRT(SUMSQ(E$6:E$105))) | P21: =IF(F21="","",F21/SQRT(SUMSQ(F$6:F$105))) | Q21: =IF(G21="","",G21/SQRT(SUMSQ(G$6:G$105))) | R21: =IF(H21="","",H21/SQRT(SUMSQ(H$6:H$105))) | S21: =IF(I21="","",I21/SQRT(SUMSQ(I$6:I$105))) | T21: =IF(J21="","",J21/SQRT(SUMSQ(J$6:J$105))) | U21: =IF(L21="","",L21*DATA!B4) | V21: =IF(M21="","",M21*DATA!C4) | W21: =IF(N21="","",N21*DATA!D4) | X21: =IF(O21="","",O21*DATA!E4) | Y21: =IF(P21="","",P21*DATA!F4) | Z21: =IF(Q21="","",Q21*DATA!G4) | AA21: =IF(R21="","",R21*DATA!H4) | AB21: =IF(S21="","",S21*DATA!I4) | AC21: =IF(T21="","",T21*DATA!J4) | AD21: =IF(U21="","",SQRT(SUMPRODUCT((U21:AC21-U127:AC127)^2))) | AE21: =IF(U21="","",SQRT(SUMPRODUCT((U21:AC21-U114:AC114)^2))) | AF21: =IF(OR(AD21="",AE21=""),"",AE21/(AD21+AE21))
A22: =IF(DATA!A24="","",DATA!A24) | B22: =IF(DATA!B24="","",DATA!B24) | H22: =IF(DATA!H24="","",DATA!H24) | I22: =IF(DATA!I24="","",DATA!I24) | J22: =IF(DATA!J24="","",DATA!J24) | L22: =IF(B22="","",B22/SQRT(SUMSQ(B$6:B$105))) | M22: =IF(C22="","",C22/SQRT(SUMSQ(C$6:C$105))) | N22: =IF(D22="","",D22/SQRT(SUMSQ(D$6:D$105))) | O22: =IF(E22="","",E22/SQRT(SUMSQ(E$6:E$105))) | P22: =IF(F22="","",F22/SQRT(SUMSQ(F$6:F$105))) | Q22: =IF(G22="","",G22/SQRT(SUMSQ(G$6:G$105))) | R22: =IF(H22="","",H22/SQRT(SUMSQ(H$6:H$105))) | S22: =IF(I22="","",I22/SQRT(SUMSQ(I$6:I$105))) | T22: =IF(J22="","",J22/SQRT(SUMSQ(J$6:J$105))) | U22: =IF(L22="","",L22*DATA!B4) | V22: =IF(M22="","",M22*DATA!C4) | W22: =IF(N22="","",N22*DATA!D4) | X22: =IF(O22="","",O22*DATA!E4) | Y22: =IF(P22="","",P22*DATA!F4) | Z22: =IF(Q22="","",Q22*DATA!G4) | AA22: =IF(R22="","",R22*DATA!H4) | AB22: =IF(S22="","",S22*DATA!I4) | AC22: =IF(T22="","",T22*DATA!J4) | AD22: =IF(U22="","",SQRT(SUMPRODUCT((U22:AC22-U128:AC128)^2))) | AE22: =IF(U22="","",SQRT(SUMPRODUCT((U22:AC22-U114:AC114)^2))) | AF22: =IF(OR(AD22="",AE22=""),"",AE22/(AD22+AE22))
A23: =IF(DATA!A25="","",DATA!A25) | B23: =IF(DATA!B25="","",DATA!B25) | H23: =IF(DATA!H25="","",DATA!H25) | I23: =IF(DATA!I25="","",DATA!I25) | J23: =IF(DATA!J25="","",DATA!J25) | L23: =IF(B23="","",B23/SQRT(SUMSQ(B$6:B$105))) | M23: =IF(C23="","",C23/SQRT(SUMSQ(C$6:C$105))) | N23: =IF(D23="","",D23/SQRT(SUMSQ(D$6:D$105))) | O23: =IF(E23="","",E23/SQRT(SUMSQ(E$6:E$105))) | P23: =IF(F23="","",F23/SQRT(SUMSQ(F$6:F$105))) | Q23: =IF(G23="","",G23/SQRT(SUMSQ(G$6:G$105))) | R23: =IF(H23="","",H23/SQRT(SUMSQ(H$6:H$105))) | S23: =IF(I23="","",I23/SQRT(SUMSQ(I$6:I$105))) | T23: =IF(J23="","",J23/SQRT(SUMSQ(J$6:J$105))) | U23: =IF(L23="","",L23*DATA!B4) | V23: =IF(M23="","",M23*DATA!C4) | W23: =IF(N23="","",N23*DATA!D4) | X23: =IF(O23="","",O23*DATA!E4) | Y23: =IF(P23="","",P23*DATA!F4) | Z23: =IF(Q23="","",Q23*DATA!G4) | AA23: =IF(R23="","",R23*DATA!H4) | AB23: =IF(S23="","",S23*DATA!I4) | AC23: =IF(T23="","",T23*DATA!J4) | AD23: =IF(U23="","",SQRT(SUMPRODUCT((U23:AC23-U129:AC129)^2))) | AE23: =IF(U23="","",SQRT(SUMPRODUCT((U23:AC23-U114:AC114)^2))) | AF23: =IF(OR(AD23="",AE23=""),"",AE23/(AD23+AE23))
A24: =IF(DATA!A26="","",DATA!A26) | B24: =IF(DATA!B26="","",DATA!B26) | H24: =IF(DATA!H26="","",DATA!H26) | I24: =IF(DATA!I26="","",DATA!I26) | J24: =IF(DATA!J26="","",DATA!J26) | L24: =IF(B24="","",B24/SQRT(SUMSQ(B$6:B$105))) | M24: =IF(C24="","",C24/SQRT(SUMSQ(C$6:C$105))) | N24: =IF(D24="","",D24/SQRT(SUMSQ(D$6:D$105))) | O24: =IF(E24="","",E24/SQRT(SUMSQ(E$6:E$105))) | P24: =IF(F24="","",F24/SQRT(SUMSQ(F$6:F$105))) | Q24: =IF(G24="","",G24/SQRT(SUMSQ(G$6:G$105))) | R24: =IF(H24="","",H24/SQRT(SUMSQ(H$6:H$105))) | S24: =IF(I24="","",I24/SQRT(SUMSQ(I$6:I$105))) | T24: =IF(J24="","",J24/SQRT(SUMSQ(J$6:J$105))) | U24: =IF(L24="","",L24*DATA!B4) | V24: =IF(M24="","",M24*DATA!C4) | W24: =IF(N24="","",N24*DATA!D4) | X24: =IF(O24="","",O24*DATA!E4) | Y24: =IF(P24="","",P24*DATA!F4) | Z24: =IF(Q24="","",Q24*DATA!G4) | AA24: =IF(R24="","",R24*DATA!H4) | AB24: =IF(S24="","",S24*DATA!I4) | AC24: =IF(T24="","",T24*DATA!J4) | AD24: =IF(U24="","",SQRT(SUMPRODUCT((U24:AC24-U130:AC130)^2))) | AE24: =IF(U24="","",SQRT(SUMPRODUCT((U24:AC24-U114:AC114)^2))) | AF24: =IF(OR(AD24="",AE24=""),"",AE24/(AD24+AE24))
A25: =IF(DATA!A27="","",DATA!A27) | B25: =IF(DATA!B27="","",DATA!B27) | C25: =IF(DATA!C27="","",DATA!C27) | D25: =IF(DATA!D27="","",DATA!D27) | E25: =IF(DATA!E27="","",DATA!E27) | F25: =IF(DATA!F27="","",DATA!F27) | G25: =IF(DATA!G27="","",DATA!G27) | H25: =IF(DATA!H27="","",DATA!H27) | ... J25: =IF(DATA!J27="","",DATA!J27) | L25: =IF(B25="","",B25/SQRT(SUMSQ(B$6:B$105))) | M25: =IF(C25="","",C25/SQRT(SUMSQ(C$6:C$105))) | N25: =IF(D25="","",D25/SQRT(SUMSQ(D$6:D$105))) | O25: =IF(E25="","",E25/SQRT(SUMSQ(E$6:E$105))) | P25: =IF(F25="","",F25/SQRT(SUMSQ(F$6:F$105))) | Q25: =IF(G25="","",G25/SQRT(SUMSQ(G$6:G$105))) | R25: =IF(H25="","",H25/SQRT(SUMSQ(H$6:H$105))) | S25: =IF(I25="","",I25/SQRT(SUMSQ(I$6:I$105))) | T25: =IF(J25="","",J25/SQRT(SUMSQ(J$6:J$105))) | U25: =IF(L25="","",L25*DATA!B4) | V25: =IF(M25="","",M25*DATA!C4) | W25: =IF(N25="","",N25*DATA!D4) | X25: =IF(O25="","",O25*DATA!E4) | Y25: =IF(P25="","",P25*DATA!F4) | Z25: =IF(Q25="","",Q25*DATA!G4) | AA25: =IF(R25="","",R25*DATA!H4) | AB25: =IF(S25="","",S25*DATA!I4) | AC25: =IF(T25="","",T25*DATA!J4) | AD25: =IF(U25="","",SQRT(SUMPRODUCT((U25:AC25-U131:AC131)^2))) | AE25: =IF(U25="","",SQRT(SUMPRODUCT((U25:AC25-U114:AC114)^2))) | AF25: =IF(OR(AD25="",AE25=""),"",AE25/(AD25+AE25))
A26: =IF(DATA!A28="","",DATA!A28) | B26: =IF(DATA!B28="","",DATA!B28) | C26: =IF(DATA!C28="","",DATA!C28) | D26: =IF(DATA!D28="","",DATA!D28) | E26: =IF(DATA!E28="","",DATA!E28) | F26: =IF(DATA!F28="","",DATA!F28) | G26: =IF(DATA!G28="","",DATA!G28) | H26: =IF(DATA!H28="","",DATA!H28) | ... J26: =IF(DATA!J28="","",DATA!J28) | L26: =IF(B26="","",B26/SQRT(SUMSQ(B$6:B$105))) | M26: =IF(C26="","",C26/SQRT(SUMSQ(C$6:C$105))) | N26: =IF(D26="","",D26/SQRT(SUMSQ(D$6:D$105))) | O26: =IF(E26="","",E26/SQRT(SUMSQ(E$6:E$105))) | P26: =IF(F26="","",F26/SQRT(SUMSQ(F$6:F$105))) | Q26: =IF(G26="","",G26/SQRT(SUMSQ(G$6:G$105))) | R26: =IF(H26="","",H26/SQRT(SUMSQ(H$6:H$105))) | S26: =IF(I26="","",I26/SQRT(SUMSQ(I$6:I$105))) | T26: =IF(J26="","",J26/SQRT(SUMSQ(J$6:J$105))) | U26: =IF(L26="","",L26*DATA!B4) | V26: =IF(M26="","",M26*DATA!C4) | W26: =IF(N26="","",N26*DATA!D4) | X26: =IF(O26="","",O26*DATA!E4) | Y26: =IF(P26="","",P26*DATA!F4) | Z26: =IF(Q26="","",Q26*DATA!G4) | AA26: =IF(R26="","",R26*DATA!H4) | AB26: =IF(S26="","",S26*DATA!I4) | AC26: =IF(T26="","",T26*DATA!J4) | AD26: =IF(U26="","",SQRT(SUMPRODUCT((U26:AC26-U132:AC132)^2))) | AE26: =IF(U26="","",SQRT(SUMPRODUCT((U26:AC26-U114:AC114)^2))) | AF26: =IF(OR(AD26="",AE26=""),"",AE26/(AD26+AE26))
A27: =IF(DATA!A29="","",DATA!A29) | B27: =IF(DATA!B29="","",DATA!B29) | C27: =IF(DATA!C29="","",DATA!C29) | D27: =IF(DATA!D29="","",DATA!D29) | E27: =IF(DATA!E29="","",DATA!E29) | F27: =IF(DATA!F29="","",DATA!F29) | G27: =IF(DATA!G29="","",DATA!G29) | H27: =IF(DATA!H29="","",DATA!H29) | ... J27: =IF(DATA!J29="","",DATA!J29) | L27: =IF(B27="","",B27/SQRT(SUMSQ(B$6:B$105))) | M27: =IF(C27="","",C27/SQRT(SUMSQ(C$6:C$105))) | N27: =IF(D27="","",D27/SQRT(SUMSQ(D$6:D$105))) | O27: =IF(E27="","",E27/SQRT(SUMSQ(E$6:E$105))) | P27: =IF(F27="","",F27/SQRT(SUMSQ(F$6:F$105))) | Q27: =IF(G27="","",G27/SQRT(SUMSQ(G$6:G$105))) | R27: =IF(H27="","",H27/SQRT(SUMSQ(H$6:H$105))) | S27: =IF(I27="","",I27/SQRT(SUMSQ(I$6:I$105))) | T27: =IF(J27="","",J27/SQRT(SUMSQ(J$6:J$105))) | U27: =IF(L27="","",L27*DATA!B4) | V27: =IF(M27="","",M27*DATA!C4) | W27: =IF(N27="","",N27*DATA!D4) | X27: =IF(O27="","",O27*DATA!E4) | Y27: =IF(P27="","",P27*DATA!F4) | Z27: =IF(Q27="","",Q27*DATA!G4) | AA27: =IF(R27="","",R27*DATA!H4) | AB27: =IF(S27="","",S27*DATA!I4) | AC27: =IF(T27="","",T27*DATA!J4) | AD27: =IF(U27="","",SQRT(SUMPRODUCT((U27:AC27-U133:AC133)^2))) | AE27: =IF(U27="","",SQRT(SUMPRODUCT((U27:AC27-U114:AC114)^2))) | AF27: =IF(OR(AD27="",AE27=""),"",AE27/(AD27+AE27))
A28: =IF(DATA!A30="","",DATA!A30) | B28: =IF(DATA!B30="","",DATA!B30) | C28: =IF(DATA!C30="","",DATA!C30) | D28: =IF(DATA!D30="","",DATA!D30) | E28: =IF(DATA!E30="","",DATA!E30) | F28: =IF(DATA!F30="","",DATA!F30) | G28: =IF(DATA!G30="","",DATA!G30) | H28: =IF(DATA!H30="","",DATA!H30) | ... J28: =IF(DATA!J30="","",DATA!J30) | L28: =IF(B28="","",B28/SQRT(SUMSQ(B$6:B$105))) | M28: =IF(C28="","",C28/SQRT(SUMSQ(C$6:C$105))) | N28: =IF(D28="","",D28/SQRT(SUMSQ(D$6:D$105))) | O28: =IF(E28="","",E28/SQRT(SUMSQ(E$6:E$105))) | P28: =IF(F28="","",F28/SQRT(SUMSQ(F$6:F$105))) | Q28: =IF(G28="","",G28/SQRT(SUMSQ(G$6:G$105))) | R28: =IF(H28="","",H28/SQRT(SUMSQ(H$6:H$105))) | S28: =IF(I28="","",I28/SQRT(SUMSQ(I$6:I$105))) | T28: =IF(J28="","",J28/SQRT(SUMSQ(J$6:J$105))) | U28: =IF(L28="","",L28*DATA!B4) | V28: =IF(M28="","",M28*DATA!C4) | W28: =IF(N28="","",N28*DATA!D4) | X28: =IF(O28="","",O28*DATA!E4) | Y28: =IF(P28="","",P28*DATA!F4) | Z28: =IF(Q28="","",Q28*DATA!G4) | AA28: =IF(R28="","",R28*DATA!H4) | AB28: =IF(S28="","",S28*DATA!I4) | AC28: =IF(T28="","",T28*DATA!J4) | AD28: =IF(U28="","",SQRT(SUMPRODUCT((U28:AC28-U134:AC134)^2))) | AE28: =IF(U28="","",SQRT(SUMPRODUCT((U28:AC28-U114:AC114)^2))) | AF28: =IF(OR(AD28="",AE28=""),"",AE28/(AD28+AE28))
A29: =IF(DATA!A31="","",DATA!A31) | B29: =IF(DATA!B31="","",DATA!B31) | C29: =IF(DATA!C31="","",DATA!C31) | D29: =IF(DATA!D31="","",DATA!D31) | E29: =IF(DATA!E31="","",DATA!E31) | F29: =IF(DATA!F31="","",DATA!F31) | G29: =IF(DATA!G31="","",DATA!G31) | H29: =IF(DATA!H31="","",DATA!H31) | ... J29: =IF(DATA!J31="","",DATA!J31) | L29: =IF(B29="","",B29/SQRT(SUMSQ(B$6:B$105))) | M29: =IF(C29="","",C29/SQRT(SUMSQ(C$6:C$105))) | N29: =IF(D29="","",D29/SQRT(SUMSQ(D$6:D$105))) | O29: =IF(E29="","",E29/SQRT(SUMSQ(E$6:E$105))) | P29: =IF(F29="","",F29/SQRT(SUMSQ(F$6:F$105))) | Q29: =IF(G29="","",G29/SQRT(SUMSQ(G$6:G$105))) | R29: =IF(H29="","",H29/SQRT(SUMSQ(H$6:H$105))) | S29: =IF(I29="","",I29/SQRT(SUMSQ(I$6:I$105))) | T29: =IF(J29="","",J29/SQRT(SUMSQ(J$6:J$105))) | U29: =IF(L29="","",L29*DATA!B4) | V29: =IF(M29="","",M29*DATA!C4) | W29: =IF(N29="","",N29*DATA!D4) | X29: =IF(O29="","",O29*DATA!E4) | Y29: =IF(P29="","",P29*DATA!F4) | Z29: =IF(Q29="","",Q29*DATA!G4) | AA29: =IF(R29="","",R29*DATA!H4) | AB29: =IF(S29="","",S29*DATA!I4) | AC29: =IF(T29="","",T29*DATA!J4) | AD29: =IF(U29="","",SQRT(SUMPRODUCT((U29:AC29-U135:AC135)^2))) | AE29: =IF(U29="","",SQRT(SUMPRODUCT((U29:AC29-U114:AC114)^2))) | AF29: =IF(OR(AD29="",AE29=""),"",AE29/(AD29+AE29))
A30: =IF(DATA!A32="","",DATA!A32) | B30: =IF(DATA!B32="","",DATA!B32) | C30: =IF(DATA!C32="","",DATA!C32) | D30: =IF(DATA!D32="","",DATA!D32) | E30: =IF(DATA!E32="","",DATA!E32) | F30: =IF(DATA!F32="","",DATA!F32) | G30: =IF(DATA!G32="","",DATA!G32) | H30: =IF(DATA!H32="","",DATA!H32) | ... J30: =IF(DATA!J32="","",DATA!J32) | L30: =IF(B30="","",B30/SQRT(SUMSQ(B$6:B$105))) | M30: =IF(C30="","",C30/SQRT(SUMSQ(C$6:C$105))) | N30: =IF(D30="","",D30/SQRT(SUMSQ(D$6:D$105))) | O30: =IF(E30="","",E30/SQRT(SUMSQ(E$6:E$105))) | P30: =IF(F30="","",F30/SQRT(SUMSQ(F$6:F$105))) | Q30: =IF(G30="","",G30/SQRT(SUMSQ(G$6:G$105))) | R30: =IF(H30="","",H30/SQRT(SUMSQ(H$6:H$105))) | S30: =IF(I30="","",I30/SQRT(SUMSQ(I$6:I$105))) | T30: =IF(J30="","",J30/SQRT(SUMSQ(J$6:J$105))) | U30: =IF(L30="","",L30*DATA!B4) | V30: =IF(M30="","",M30*DATA!C4) | W30: =IF(N30="","",N30*DATA!D4) | X30: =IF(O30="","",O30*DATA!E4) | Y30: =IF(P30="","",P30*DATA!F4) | Z30: =IF(Q30="","",Q30*DATA!G4) | AA30: =IF(R30="","",R30*DATA!H4) | AB30: =IF(S30="","",S30*DATA!I4) | AC30: =IF(T30="","",T30*DATA!J4) | AD30: =IF(U30="","",SQRT(SUMPRODUCT((U30:AC30-U136:AC136)^2))) | AE30: =IF(U30="","",SQRT(SUMPRODUCT((U30:AC30-U114:AC114)^2))) | AF30: =IF(OR(AD30="",AE30=""),"",AE30/(AD30+AE30))
A31: =IF(DATA!A33="","",DATA!A33) | B31: =IF(DATA!B33="","",DATA!B33) | C31: =IF(DATA!C33="","",DATA!C33) | D31: =IF(DATA!D33="","",DATA!D33) | E31: =IF(DATA!E33="","",DATA!E33) | F31: =IF(DATA!F33="","",DATA!F33) | G31: =IF(DATA!G33="","",DATA!G33) | H31: =IF(DATA!H33="","",DATA!H33) | ... J31: =IF(DATA!J33="","",DATA!J33) | L31: =IF(B31="","",B31/SQRT(SUMSQ(B$6:B$105))) | M31: =IF(C31="","",C31/SQRT(SUMSQ(C$6:C$105))) | N31: =IF(D31="","",D31/SQRT(SUMSQ(D$6:D$105))) | O31: =IF(E31="","",E31/SQRT(SUMSQ(E$6:E$105))) | P31: =IF(F31="","",F31/SQRT(SUMSQ(F$6:F$105))) | Q31: =IF(G31="","",G31/SQRT(SUMSQ(G$6:G$105))) | R31: =IF(H31="","",H31/SQRT(SUMSQ(H$6:H$105))) | S31: =IF(I31="","",I31/SQRT(SUMSQ(I$6:I$105))) | T31: =IF(J31="","",J31/SQRT(SUMSQ(J$6:J$105))) | U31: =IF(L31="","",L31*DATA!B4) | V31: =IF(M31="","",M31*DATA!C4) | W31: =IF(N31="","",N31*DATA!D4) | X31: =IF(O31="","",O31*DATA!E4) | Y31: =IF(P31="","",P31*DATA!F4) | Z31: =IF(Q31="","",Q31*DATA!G4) | AA31: =IF(R31="","",R31*DATA!H4) | AB31: =IF(S31="","",S31*DATA!I4) | AC31: =IF(T31="","",T31*DATA!J4) | AD31: =IF(U31="","",SQRT(SUMPRODUCT((U31:AC31-U137:AC137)^2))) | AE31: =IF(U31="","",SQRT(SUMPRODUCT((U31:AC31-U114:AC114)^2))) | AF31: =IF(OR(AD31="",AE31=""),"",AE31/(AD31+AE31))
A32: =IF(DATA!A34="","",DATA!A34) | B32: =IF(DATA!B34="","",DATA!B34) | C32: =IF(DATA!C34="","",DATA!C34) | D32: =IF(DATA!D34="","",DATA!D34) | E32: =IF(DATA!E34="","",DATA!E34) | F32: =IF(DATA!F34="","",DATA!F34) | G32: =IF(DATA!G34="","",DATA!G34) | H32: =IF(DATA!H34="","",DATA!H34) | ... J32: =IF(DATA!J34="","",DATA!J34) | L32: =IF(B32="","",B32/SQRT(SUMSQ(B$6:B$105))) | M32: =IF(C32="","",C32/SQRT(SUMSQ(C$6:C$105))) | N32: =IF(D32="","",D32/SQRT(SUMSQ(D$6:D$105))) | O32: =IF(E32="","",E32/SQRT(SUMSQ(E$6:E$105))) | P32: =IF(F32="","",F32/SQRT(SUMSQ(F$6:F$105))) | Q32: =IF(G32="","",G32/SQRT(SUMSQ(G$6:G$105))) | R32: =IF(H32="","",H32/SQRT(SUMSQ(H$6:H$105))) | S32: =IF(I32="","",I32/SQRT(SUMSQ(I$6:I$105))) | T32: =IF(J32="","",J32/SQRT(SUMSQ(J$6:J$105))) | U32: =IF(L32="","",L32*DATA!B4) | V32: =IF(M32="","",M32*DATA!C4) | W32: =IF(N32="","",N32*DATA!D4) | X32: =IF(O32="","",O32*DATA!E4) | Y32: =IF(P32="","",P32*DATA!F4) | Z32: =IF(Q32="","",Q32*DATA!G4) | AA32: =IF(R32="","",R32*DATA!H4) | AB32: =IF(S32="","",S32*DATA!I4) | AC32: =IF(T32="","",T32*DATA!J4) | AD32: =IF(U32="","",SQRT(SUMPRODUCT((U32:AC32-U138:AC138)^2))) | AE32: =IF(U32="","",SQRT(SUMPRODUCT((U32:AC32-U114:AC114)^2))) | AF32: =IF(OR(AD32="",AE32=""),"",AE32/(AD32+AE32))
A33: =IF(DATA!A35="","",DATA!A35) | B33: =IF(DATA!B35="","",DATA!B35) | C33: =IF(DATA!C35="","",DATA!C35) | D33: =IF(DATA!D35="","",DATA!D35) | E33: =IF(DATA!E35="","",DATA!E35) | F33: =IF(DATA!F35="","",DATA!F35) | G33: =IF(DATA!G35="","",DATA!G35) | H33: =IF(DATA!H35="","",DATA!H35) | ... J33: =IF(DATA!J35="","",DATA!J35) | L33: =IF(B33="","",B33/SQRT(SUMSQ(B$6:B$105))) | M33: =IF(C33="","",C33/SQRT(SUMSQ(C$6:C$105))) | N33: =IF(D33="","",D33/SQRT(SUMSQ(D$6:D$105))) | O33: =IF(E33="","",E33/SQRT(SUMSQ(E$6:E$105))) | P33: =IF(F33="","",F33/SQRT(SUMSQ(F$6:F$105))) | Q33: =IF(G33="","",G33/SQRT(SUMSQ(G$6:G$105))) | R33: =IF(H33="","",H33/SQRT(SUMSQ(H$6:H$105))) | S33: =IF(I33="","",I33/SQRT(SUMSQ(I$6:I$105))) | T33: =IF(J33="","",J33/SQRT(SUMSQ(J$6:J$105))) | U33: =IF(L33="","",L33*DATA!B4) | V33: =IF(M33="","",M33*DATA!C4) | W33: =IF(N33="","",N33*DATA!D4) | X33: =IF(O33="","",O33*DATA!E4) | Y33: =IF(P33="","",P33*DATA!F4) | Z33: =IF(Q33="","",Q33*DATA!G4) | AA33: =IF(R33="","",R33*DATA!H4) | AB33: =IF(S33="","",S33*DATA!I4) | AC33: =IF(T33="","",T33*DATA!J4) | AD33: =IF(U33="","",SQRT(SUMPRODUCT((U33:AC33-U139:AC139)^2))) | AE33: =IF(U33="","",SQRT(SUMPRODUCT((U33:AC33-U114:AC114)^2))) | AF33: =IF(OR(AD33="",AE33=""),"",AE33/(AD33+AE33))
A34: =IF(DATA!A36="","",DATA!A36) | B34: =IF(DATA!B36="","",DATA!B36) | C34: =IF(DATA!C36="","",DATA!C36) | D34: =IF(DATA!D36="","",DATA!D36) | E34: =IF(DATA!E36="","",DATA!E36) | F34: =IF(DATA!F36="","",DATA!F36) | G34: =IF(DATA!G36="","",DATA!G36) | H34: =IF(DATA!H36="","",DATA!H36) | ... J34: =IF(DATA!J36="","",DATA!J36) | L34: =IF(B34="","",B34/SQRT(SUMSQ(B$6:B$105))) | M34: =IF(C34="","",C34/SQRT(SUMSQ(C$6:C$105))) | N34: =IF(D34="","",D34/SQRT(SUMSQ(D$6:D$105))) | O34: =IF(E34="","",E34/SQRT(SUMSQ(E$6:E$105))) | P34: =IF(F34="","",F34/SQRT(SUMSQ(F$6:F$105))) | Q34: =IF(G34="","",G34/SQRT(SUMSQ(G$6:G$105))) | R34: =IF(H34="","",H34/SQRT(SUMSQ(H$6:H$105))) | S34: =IF(I34="","",I34/SQRT(SUMSQ(I$6:I$105))) | T34: =IF(J34="","",J34/SQRT(SUMSQ(J$6:J$105))) | U34: =IF(L34="","",L34*DATA!B4) | V34: =IF(M34="","",M34*DATA!C4) | W34: =IF(N34="","",N34*DATA!D4) | X34: =IF(O34="","",O34*DATA!E4) | Y34: =IF(P34="","",P34*DATA!F4) | Z34: =IF(Q34="","",Q34*DATA!G4) | AA34: =IF(R34="","",R34*DATA!H4) | AB34: =IF(S34="","",S34*DATA!I4) | AC34: =IF(T34="","",T34*DATA!J4) | AD34: =IF(U34="","",SQRT(SUMPRODUCT((U34:AC34-U140:AC140)^2))) | AE34: =IF(U34="","",SQRT(SUMPRODUCT((U34:AC34-U114:AC114)^2))) | AF34: =IF(OR(AD34="",AE34=""),"",AE34/(AD34+AE34))
A35: =IF(DATA!A37="","",DATA!A37) | B35: =IF(DATA!B37="","",DATA!B37) | C35: =IF(DATA!C37="","",DATA!C37) | D35: =IF(DATA!D37="","",DATA!D37) | E35: =IF(DATA!E37="","",DATA!E37) | F35: =IF(DATA!F37="","",DATA!F37) | G35: =IF(DATA!G37="","",DATA!G37) | H35: =IF(DATA!H37="","",DATA!H37) | ... J35: =IF(DATA!J37="","",DATA!J37) | L35: =IF(B35="","",B35/SQRT(SUMSQ(B$6:B$105))) | M35: =IF(C35="","",C35/SQRT(SUMSQ(C$6:C$105))) | N35: =IF(D35="","",D35/SQRT(SUMSQ(D$6:D$105))) | O35: =IF(E35="","",E35/SQRT(SUMSQ(E$6:E$105))) | P35: =IF(F35="","",F35/SQRT(SUMSQ(F$6:F$105))) | Q35: =IF(G35="","",G35/SQRT(SUMSQ(G$6:G$105))) | R35: =IF(H35="","",H35/SQRT(SUMSQ(H$6:H$105))) | S35: =IF(I35="","",I35/SQRT(SUMSQ(I$6:I$105))) | T35: =IF(J35="","",J35/SQRT(SUMSQ(J$6:J$105))) | U35: =IF(L35="","",L35*DATA!B4) | V35: =IF(M35="","",M35*DATA!C4) | W35: =IF(N35="","",N35*DATA!D4) | X35: =IF(O35="","",O35*DATA!E4) | Y35: =IF(P35="","",P35*DATA!F4) | Z35: =IF(Q35="","",Q35*DATA!G4) | AA35: =IF(R35="","",R35*DATA!H4) | AB35: =IF(S35="","",S35*DATA!I4) | AC35: =IF(T35="","",T35*DATA!J4) | AD35: =IF(U35="","",SQRT(SUMPRODUCT((U35:AC35-U141:AC141)^2))) | AE35: =IF(U35="","",SQRT(SUMPRODUCT((U35:AC35-U114:AC114)^2))) | AF35: =IF(OR(AD35="",AE35=""),"",AE35/(AD35+AE35))
A36: =IF(DATA!A38="","",DATA!A38) | B36: =IF(DATA!B38="","",DATA!B38) | C36: =IF(DATA!C38="","",DATA!C38) | D36: =IF(DATA!D38="","",DATA!D38) | E36: =IF(DATA!E38="","",DATA!E38) | F36: =IF(DATA!F38="","",DATA!F38) | G36: =IF(DATA!G38="","",DATA!G38) | H36: =IF(DATA!H38="","",DATA!H38) | ... J36: =IF(DATA!J38="","",DATA!J38) | L36: =IF(B36="","",B36/SQRT(SUMSQ(B$6:B$105))) | M36: =IF(C36="","",C36/SQRT(SUMSQ(C$6:C$105))) | N36: =IF(D36="","",D36/SQRT(SUMSQ(D$6:D$105))) | O36: =IF(E36="","",E36/SQRT(SUMSQ(E$6:E$105))) | P36: =IF(F36="","",F36/SQRT(SUMSQ(F$6:F$105))) | Q36: =IF(G36="","",G36/SQRT(SUMSQ(G$6:G$105))) | R36: =IF(H36="","",H36/SQRT(SUMSQ(H$6:H$105))) | S36: =IF(I36="","",I36/SQRT(SUMSQ(I$6:I$105))) | T36: =IF(J36="","",J36/SQRT(SUMSQ(J$6:J$105))) | U36: =IF(L36="","",L36*DATA!B4) | V36: =IF(M36="","",M36*DATA!C4) | W36: =IF(N36="","",N36*DATA!D4) | X36: =IF(O36="","",O36*DATA!E4) | Y36: =IF(P36="","",P36*DATA!F4) | Z36: =IF(Q36="","",Q36*DATA!G4) | AA36: =IF(R36="","",R36*DATA!H4) | AB36: =IF(S36="","",S36*DATA!I4) | AC36: =IF(T36="","",T36*DATA!J4) | AD36: =IF(U36="","",SQRT(SUMPRODUCT((U36:AC36-U142:AC142)^2))) | AE36: =IF(U36="","",SQRT(SUMPRODUCT((U36:AC36-U114:AC114)^2))) | AF36: =IF(OR(AD36="",AE36=""),"",AE36/(AD36+AE36))
